<mujoco model="go1">
  <compiler angle="radian" meshdir="xmls/assets" autolimits="true"/>

  <option iterations="1" ls_iterations="5" timestep="0.004" integrator="Euler">
    <flag eulerdamp="disable"/>
  </option>

  <default>
    <default class="go1">
      <geom condim="1" contype="0" conaffinity="1"/>
      <joint axis="0 1 0" armature="0.005" damping="0.5"/>
      <position forcerange="-23.7 23.7" inheritrange="1" kp="35"/>
      <default class="abduction">
        <joint axis="1 0 0" range="-0.863 0.863" frictionloss="0.3"/>
      </default>
      <default class="hip">
        <joint range="-0.686 4.501" frictionloss="0.3"/>
      </default>
      <default class="knee">
        <joint range="-2.818 -0.888" frictionloss="1.0"/>
        <position forcerange="-35.55 35.55"/>
      </default>
      <default class="visual">
        <geom type="mesh" contype="0" conaffinity="0" group="2" material="dark"/>
      </default>
      <default class="collision">
        <geom group="3" type="capsule"/>
        <default class="hip_left1">
          <geom size="0.046 0.02" pos="0 0.045 0" quat="1 1 0 0" type="cylinder"/>
        </default>
        <default class="hip_left2">
          <geom size="0.031 0.02" pos="0 0.065 0" quat="1 1 0 0" type="cylinder"/>
        </default>
        <default class="hip_left3">
          <geom size="0.046 0.02" quat="1 1 0 0" type="cylinder"/>
        </default>
        <default class="hip_right1">
          <geom size="0.046 0.02" pos="0 -0.045 0" quat="1 1 0 0" type="cylinder"/>
        </default>
        <default class="hip_right2">
          <geom size="0.031 0.02" pos="0 -0.065 0" quat="1 1 0 0" type="cylinder"/>
        </default>
        <default class="hip_right3">
          <geom size="0.046 0.02" quat="1 1 0 0" type="cylinder"/>
        </default>
        <default class="thigh1">
          <geom size="0.015" fromto="-0.02 0 0 -0.02 0 -0.16"/>
        </default>
        <default class="thigh2">
          <geom size="0.015" fromto="0 0 0 -0.02 0 -0.1"/>
        </default>
        <default class="thigh3">
          <geom size="0.015" fromto="-0.02 0 -0.16 0 0 -0.2"/>
        </default>
        <default class="calf1">
          <geom size="0.01" fromto="0 0 0 0.02 0 -0.13"/>
        </default>
        <default class="calf2">
          <geom size="0.01" fromto="0.02 0 -0.13 0 0 -0.2"/>
        </default>
        <default class="foot">
          <geom type="sphere" size="0.023" pos="0 0 -0.213" solimp="0.9 .95 0.023" condim="3"/>
        </default>
      </default>
    </default>
  </default>

  <asset>
    <material name="dark" rgba="0.2 0.2 0.2 1"/>
    <mesh class="go1" file="trunk.stl"/>
    <mesh class="go1" file="hip.stl"/>
    <mesh class="go1" file="thigh_mirror.stl"/>
    <mesh class="go1" file="calf.stl"/>
    <mesh class="go1" file="thigh.stl"/>
  </asset>

  <worldbody>
    <light name="spotlight" mode="targetbodycom" target="trunk" pos="3 0 4"/>
    <body name="trunk" pos="0 0 0.445" childclass="go1">
      <camera name="track" pos="0.846 -1.3 0.316" xyaxes="0.866 0.500 0.000 -0.171 0.296 0.940" mode="trackcom"/>
      <camera name="top" pos="-1 0 1" xyaxes="0 -1 0 0.7 0 0.7" mode="trackcom"/>
      <camera name="side" pos="0 -1 .3" xyaxes="1 0 0 0 1 2" mode="trackcom"/>
      <camera name="back" pos="-1 0 .3" xyaxes="0 -1 0 1 0 2" mode="trackcom"/>
      <camera name="robot_cam" pos="0.2 0 0.32" euler="1.57 3.14 0" mode="targetbody" target="head_dummy"/>
      <site name="head" pos="0.3 0 0" rgba="1 0 0 1" size="0.02" group="5"/>
      <inertial pos="0.0223 0.002 -0.0005" quat="-0.00342088 0.705204 0.000106698 0.708996" mass="5.204"
        diaginertia="0.0716565 0.0630105 0.0168101"/>
      <freejoint/>
      <geom class="visual" mesh="trunk"/>
      <geom class="collision" quat="1 0 1 0" pos="0 -0.04 0" size="0.058 0.125" type="cylinder"/>
      <geom class="collision" quat="1 0 1 0" pos="0 +0.04 0" size="0.058 0.125" type="cylinder"/>
      <site name="imu" pos="-0.01592 -0.06659 -0.00617" group="5"/>
      <body name="head_dummy" pos="0.5 0.0 0.12">
      </body>
      
      <site name="lidar_-60" type="box" size="0.1 0.1 0.1" pos="0 0 0.3" rgba="0 1 0 0" zaxis="0.5 -0.866 0" group="5"/>
      <site name="lidar_-59" type="box" size="0.1 0.1 0.1" pos="0 0 0.3" rgba="0 1 0 0" zaxis="0.515 -0.857 0" group="5"/>
      <site name="lidar_-58" type="box" size="0.1 0.1 0.1" pos="0 0 0.3" rgba="0 1 0 0" zaxis="0.53 -0.848 0" group="5"/>
      <site name="lidar_-57" type="box" size="0.1 0.1 0.1" pos="0 0 0.3" rgba="0 1 0 0" zaxis="0.545 -0.839 0" group="5"/>
      <site name="lidar_-56" type="box" size="0.1 0.1 0.1" pos="0 0 0.3" rgba="0 1 0 0" zaxis="0.559 -0.829 0" group="5"/>
      <site name="lidar_-55" type="box" size="0.1 0.1 0.1" pos="0 0 0.3" rgba="0 1 0 0" zaxis="0.574 -0.819 0" group="5"/>
      <site name="lidar_-54" type="box" size="0.1 0.1 0.1" pos="0 0 0.3" rgba="0 1 0 0" zaxis="0.588 -0.809 0" group="5"/>
      <site name="lidar_-53" type="box" size="0.1 0.1 0.1" pos="0 0 0.3" rgba="0 1 0 0" zaxis="0.602 -0.799 0" group="5"/>
      <site name="lidar_-52" type="box" size="0.1 0.1 0.1" pos="0 0 0.3" rgba="0 1 0 0" zaxis="0.616 -0.788 0" group="5"/>
      <site name="lidar_-51" type="box" size="0.1 0.1 0.1" pos="0 0 0.3" rgba="0 1 0 0" zaxis="0.629 -0.777 0" group="5"/>
      <site name="lidar_-50" type="box" size="0.1 0.1 0.1" pos="0 0 0.3" rgba="0 1 0 0" zaxis="0.643 -0.766 0" group="5"/>
      <site name="lidar_-49" type="box" size="0.1 0.1 0.1" pos="0 0 0.3" rgba="0 1 0 0" zaxis="0.656 -0.755 0" group="5"/>
      <site name="lidar_-48" type="box" size="0.1 0.1 0.1" pos="0 0 0.3" rgba="0 1 0 0" zaxis="0.669 -0.743 0" group="5"/>
      <site name="lidar_-47" type="box" size="0.1 0.1 0.1" pos="0 0 0.3" rgba="0 1 0 0" zaxis="0.682 -0.731 0" group="5"/>
      <site name="lidar_-46" type="box" size="0.1 0.1 0.1" pos="0 0 0.3" rgba="0 1 0 0" zaxis="0.695 -0.719 0" group="5"/>
      <site name="lidar_-45" type="box" size="0.1 0.1 0.1" pos="0 0 0.3" rgba="0 1 0 0" zaxis="0.707 -0.707 0" group="5"/>
      <site name="lidar_-44" type="box" size="0.1 0.1 0.1" pos="0 0 0.3" rgba="0 1 0 0" zaxis="0.719 -0.695 0" group="5"/>
      <site name="lidar_-43" type="box" size="0.1 0.1 0.1" pos="0 0 0.3" rgba="0 1 0 0" zaxis="0.731 -0.682 0" group="5"/>
      <site name="lidar_-42" type="box" size="0.1 0.1 0.1" pos="0 0 0.3" rgba="0 1 0 0" zaxis="0.743 -0.669 0" group="5"/>
      <site name="lidar_-41" type="box" size="0.1 0.1 0.1" pos="0 0 0.3" rgba="0 1 0 0" zaxis="0.755 -0.656 0" group="5"/>
      <site name="lidar_-40" type="box" size="0.1 0.1 0.1" pos="0 0 0.3" rgba="0 1 0 0" zaxis="0.766 -0.643 0" group="5"/>
      <site name="lidar_-39" type="box" size="0.1 0.1 0.1" pos="0 0 0.3" rgba="0 1 0 0" zaxis="0.777 -0.629 0" group="5"/>
      <site name="lidar_-38" type="box" size="0.1 0.1 0.1" pos="0 0 0.3" rgba="0 1 0 0" zaxis="0.788 -0.616 0" group="5"/>
      <site name="lidar_-37" type="box" size="0.1 0.1 0.1" pos="0 0 0.3" rgba="0 1 0 0" zaxis="0.799 -0.602 0" group="5"/>
      <site name="lidar_-36" type="box" size="0.1 0.1 0.1" pos="0 0 0.3" rgba="0 1 0 0" zaxis="0.809 -0.588 0" group="5"/>
      <site name="lidar_-35" type="box" size="0.1 0.1 0.1" pos="0 0 0.3" rgba="0 1 0 0" zaxis="0.819 -0.574 0" group="5"/>
      <site name="lidar_-34" type="box" size="0.1 0.1 0.1" pos="0 0 0.3" rgba="0 1 0 0" zaxis="0.829 -0.559 0" group="5"/>
      <site name="lidar_-33" type="box" size="0.1 0.1 0.1" pos="0 0 0.3" rgba="0 1 0 0" zaxis="0.839 -0.545 0" group="5"/>
      <site name="lidar_-32" type="box" size="0.1 0.1 0.1" pos="0 0 0.3" rgba="0 1 0 0" zaxis="0.848 -0.53 0" group="5"/>
      <site name="lidar_-31" type="box" size="0.1 0.1 0.1" pos="0 0 0.3" rgba="0 1 0 0" zaxis="0.857 -0.515 0" group="5"/>
      <site name="lidar_-30" type="box" size="0.1 0.1 0.1" pos="0 0 0.3" rgba="0 1 0 0" zaxis="0.866 -0.5 0" group="5"/>
      <site name="lidar_-29" type="box" size="0.1 0.1 0.1" pos="0 0 0.3" rgba="0 1 0 0" zaxis="0.875 -0.485 0" group="5"/>
      <site name="lidar_-28" type="box" size="0.1 0.1 0.1" pos="0 0 0.3" rgba="0 1 0 0" zaxis="0.883 -0.469 0" group="5"/>
      <site name="lidar_-27" type="box" size="0.1 0.1 0.1" pos="0 0 0.3" rgba="0 1 0 0" zaxis="0.891 -0.454 0" group="5"/>
      <site name="lidar_-26" type="box" size="0.1 0.1 0.1" pos="0 0 0.3" rgba="0 1 0 0" zaxis="0.899 -0.438 0" group="5"/>
      <site name="lidar_-25" type="box" size="0.1 0.1 0.1" pos="0 0 0.3" rgba="0 1 0 0" zaxis="0.906 -0.423 0" group="5"/>
      <site name="lidar_-24" type="box" size="0.1 0.1 0.1" pos="0 0 0.3" rgba="0 1 0 0" zaxis="0.914 -0.407 0" group="5"/>
      <site name="lidar_-23" type="box" size="0.1 0.1 0.1" pos="0 0 0.3" rgba="0 1 0 0" zaxis="0.921 -0.391 0" group="5"/>
      <site name="lidar_-22" type="box" size="0.1 0.1 0.1" pos="0 0 0.3" rgba="0 1 0 0" zaxis="0.927 -0.375 0" group="5"/>
      <site name="lidar_-21" type="box" size="0.1 0.1 0.1" pos="0 0 0.3" rgba="0 1 0 0" zaxis="0.934 -0.358 0" group="5"/>
      <site name="lidar_-20" type="box" size="0.1 0.1 0.1" pos="0 0 0.3" rgba="0 1 0 0" zaxis="0.94 -0.342 0" group="5"/>
      <site name="lidar_-19" type="box" size="0.1 0.1 0.1" pos="0 0 0.3" rgba="0 1 0 0" zaxis="0.946 -0.326 0" group="5"/>
      <site name="lidar_-18" type="box" size="0.1 0.1 0.1" pos="0 0 0.3" rgba="0 1 0 0" zaxis="0.951 -0.309 0" group="5"/>
      <site name="lidar_-17" type="box" size="0.1 0.1 0.1" pos="0 0 0.3" rgba="0 1 0 0" zaxis="0.956 -0.292 0" group="5"/>
      <site name="lidar_-16" type="box" size="0.1 0.1 0.1" pos="0 0 0.3" rgba="0 1 0 0" zaxis="0.961 -0.276 0" group="5"/>
      <site name="lidar_-15" type="box" size="0.1 0.1 0.1" pos="0 0 0.3" rgba="0 1 0 0" zaxis="0.966 -0.259 0" group="5"/>
      <site name="lidar_-14" type="box" size="0.1 0.1 0.1" pos="0 0 0.3" rgba="0 1 0 0" zaxis="0.97 -0.242 0" group="5"/>
      <site name="lidar_-13" type="box" size="0.1 0.1 0.1" pos="0 0 0.3" rgba="0 1 0 0" zaxis="0.974 -0.225 0" group="5"/>
      <site name="lidar_-12" type="box" size="0.1 0.1 0.1" pos="0 0 0.3" rgba="0 1 0 0" zaxis="0.978 -0.208 0" group="5"/>
      <site name="lidar_-11" type="box" size="0.1 0.1 0.1" pos="0 0 0.3" rgba="0 1 0 0" zaxis="0.982 -0.191 0" group="5"/>
      <site name="lidar_-10" type="box" size="0.1 0.1 0.1" pos="0 0 0.3" rgba="0 1 0 0" zaxis="0.985 -0.174 0" group="5"/>
      <site name="lidar_-9" type="box" size="0.1 0.1 0.1" pos="0 0 0.3" rgba="0 1 0 0" zaxis="0.988 -0.156 0" group="5"/>
      <site name="lidar_-8" type="box" size="0.1 0.1 0.1" pos="0 0 0.3" rgba="0 1 0 0" zaxis="0.99 -0.139 0" group="5"/>
      <site name="lidar_-7" type="box" size="0.1 0.1 0.1" pos="0 0 0.3" rgba="0 1 0 0" zaxis="0.993 -0.122 0" group="5"/>
      <site name="lidar_-6" type="box" size="0.1 0.1 0.1" pos="0 0 0.3" rgba="0 1 0 0" zaxis="0.995 -0.105 0" group="5"/>
      <site name="lidar_-5" type="box" size="0.1 0.1 0.1" pos="0 0 0.3" rgba="0 1 0 0" zaxis="0.996 -0.087 0" group="5"/>
      <site name="lidar_-4" type="box" size="0.1 0.1 0.1" pos="0 0 0.3" rgba="0 1 0 0" zaxis="0.998 -0.07 0" group="5"/>
      <site name="lidar_-3" type="box" size="0.1 0.1 0.1" pos="0 0 0.3" rgba="0 1 0 0" zaxis="0.999 -0.052 0" group="5"/>
      <site name="lidar_-2" type="box" size="0.1 0.1 0.1" pos="0 0 0.3" rgba="0 1 0 0" zaxis="0.999 -0.035 0" group="5"/>
      <site name="lidar_-1" type="box" size="0.1 0.1 0.1" pos="0 0 0.3" rgba="0 1 0 0" zaxis="1.0 -0.017 0" group="5"/>
      <site name="lidar_0" type="box" size="0.1 0.1 0.1" pos="0 0 0.3" rgba="0 1 0 0" zaxis="1.0 0.0 0" group="5"/>
      <site name="lidar_1" type="box" size="0.1 0.1 0.1" pos="0 0 0.3" rgba="0 1 0 0" zaxis="1.0 0.017 0" group="5"/>
      <site name="lidar_2" type="box" size="0.1 0.1 0.1" pos="0 0 0.3" rgba="0 1 0 0" zaxis="0.999 0.035 0" group="5"/>
      <site name="lidar_3" type="box" size="0.1 0.1 0.1" pos="0 0 0.3" rgba="0 1 0 0" zaxis="0.999 0.052 0" group="5"/>
      <site name="lidar_4" type="box" size="0.1 0.1 0.1" pos="0 0 0.3" rgba="0 1 0 0" zaxis="0.998 0.07 0" group="5"/>
      <site name="lidar_5" type="box" size="0.1 0.1 0.1" pos="0 0 0.3" rgba="0 1 0 0" zaxis="0.996 0.087 0" group="5"/>
      <site name="lidar_6" type="box" size="0.1 0.1 0.1" pos="0 0 0.3" rgba="0 1 0 0" zaxis="0.995 0.105 0" group="5"/>
      <site name="lidar_7" type="box" size="0.1 0.1 0.1" pos="0 0 0.3" rgba="0 1 0 0" zaxis="0.993 0.122 0" group="5"/>
      <site name="lidar_8" type="box" size="0.1 0.1 0.1" pos="0 0 0.3" rgba="0 1 0 0" zaxis="0.99 0.139 0" group="5"/>
      <site name="lidar_9" type="box" size="0.1 0.1 0.1" pos="0 0 0.3" rgba="0 1 0 0" zaxis="0.988 0.156 0" group="5"/>
      <site name="lidar_10" type="box" size="0.1 0.1 0.1" pos="0 0 0.3" rgba="0 1 0 0" zaxis="0.985 0.174 0" group="5"/>
      <site name="lidar_11" type="box" size="0.1 0.1 0.1" pos="0 0 0.3" rgba="0 1 0 0" zaxis="0.982 0.191 0" group="5"/>
      <site name="lidar_12" type="box" size="0.1 0.1 0.1" pos="0 0 0.3" rgba="0 1 0 0" zaxis="0.978 0.208 0" group="5"/>
      <site name="lidar_13" type="box" size="0.1 0.1 0.1" pos="0 0 0.3" rgba="0 1 0 0" zaxis="0.974 0.225 0" group="5"/>
      <site name="lidar_14" type="box" size="0.1 0.1 0.1" pos="0 0 0.3" rgba="0 1 0 0" zaxis="0.97 0.242 0" group="5"/>
      <site name="lidar_15" type="box" size="0.1 0.1 0.1" pos="0 0 0.3" rgba="0 1 0 0" zaxis="0.966 0.259 0" group="5"/>
      <site name="lidar_16" type="box" size="0.1 0.1 0.1" pos="0 0 0.3" rgba="0 1 0 0" zaxis="0.961 0.276 0" group="5"/>
      <site name="lidar_17" type="box" size="0.1 0.1 0.1" pos="0 0 0.3" rgba="0 1 0 0" zaxis="0.956 0.292 0" group="5"/>
      <site name="lidar_18" type="box" size="0.1 0.1 0.1" pos="0 0 0.3" rgba="0 1 0 0" zaxis="0.951 0.309 0" group="5"/>
      <site name="lidar_19" type="box" size="0.1 0.1 0.1" pos="0 0 0.3" rgba="0 1 0 0" zaxis="0.946 0.326 0" group="5"/>
      <site name="lidar_20" type="box" size="0.1 0.1 0.1" pos="0 0 0.3" rgba="0 1 0 0" zaxis="0.94 0.342 0" group="5"/>
      <site name="lidar_21" type="box" size="0.1 0.1 0.1" pos="0 0 0.3" rgba="0 1 0 0" zaxis="0.934 0.358 0" group="5"/>
      <site name="lidar_22" type="box" size="0.1 0.1 0.1" pos="0 0 0.3" rgba="0 1 0 0" zaxis="0.927 0.375 0" group="5"/>
      <site name="lidar_23" type="box" size="0.1 0.1 0.1" pos="0 0 0.3" rgba="0 1 0 0" zaxis="0.921 0.391 0" group="5"/>
      <site name="lidar_24" type="box" size="0.1 0.1 0.1" pos="0 0 0.3" rgba="0 1 0 0" zaxis="0.914 0.407 0" group="5"/>
      <site name="lidar_25" type="box" size="0.1 0.1 0.1" pos="0 0 0.3" rgba="0 1 0 0" zaxis="0.906 0.423 0" group="5"/>
      <site name="lidar_26" type="box" size="0.1 0.1 0.1" pos="0 0 0.3" rgba="0 1 0 0" zaxis="0.899 0.438 0" group="5"/>
      <site name="lidar_27" type="box" size="0.1 0.1 0.1" pos="0 0 0.3" rgba="0 1 0 0" zaxis="0.891 0.454 0" group="5"/>
      <site name="lidar_28" type="box" size="0.1 0.1 0.1" pos="0 0 0.3" rgba="0 1 0 0" zaxis="0.883 0.469 0" group="5"/>
      <site name="lidar_29" type="box" size="0.1 0.1 0.1" pos="0 0 0.3" rgba="0 1 0 0" zaxis="0.875 0.485 0" group="5"/>
      <site name="lidar_30" type="box" size="0.1 0.1 0.1" pos="0 0 0.3" rgba="0 1 0 0" zaxis="0.866 0.5 0" group="5"/>
      <site name="lidar_31" type="box" size="0.1 0.1 0.1" pos="0 0 0.3" rgba="0 1 0 0" zaxis="0.857 0.515 0" group="5"/>
      <site name="lidar_32" type="box" size="0.1 0.1 0.1" pos="0 0 0.3" rgba="0 1 0 0" zaxis="0.848 0.53 0" group="5"/>
      <site name="lidar_33" type="box" size="0.1 0.1 0.1" pos="0 0 0.3" rgba="0 1 0 0" zaxis="0.839 0.545 0" group="5"/>
      <site name="lidar_34" type="box" size="0.1 0.1 0.1" pos="0 0 0.3" rgba="0 1 0 0" zaxis="0.829 0.559 0" group="5"/>
      <site name="lidar_35" type="box" size="0.1 0.1 0.1" pos="0 0 0.3" rgba="0 1 0 0" zaxis="0.819 0.574 0" group="5"/>
      <site name="lidar_36" type="box" size="0.1 0.1 0.1" pos="0 0 0.3" rgba="0 1 0 0" zaxis="0.809 0.588 0" group="5"/>
      <site name="lidar_37" type="box" size="0.1 0.1 0.1" pos="0 0 0.3" rgba="0 1 0 0" zaxis="0.799 0.602 0" group="5"/>
      <site name="lidar_38" type="box" size="0.1 0.1 0.1" pos="0 0 0.3" rgba="0 1 0 0" zaxis="0.788 0.616 0" group="5"/>
      <site name="lidar_39" type="box" size="0.1 0.1 0.1" pos="0 0 0.3" rgba="0 1 0 0" zaxis="0.777 0.629 0" group="5"/>
      <site name="lidar_40" type="box" size="0.1 0.1 0.1" pos="0 0 0.3" rgba="0 1 0 0" zaxis="0.766 0.643 0" group="5"/>
      <site name="lidar_41" type="box" size="0.1 0.1 0.1" pos="0 0 0.3" rgba="0 1 0 0" zaxis="0.755 0.656 0" group="5"/>
      <site name="lidar_42" type="box" size="0.1 0.1 0.1" pos="0 0 0.3" rgba="0 1 0 0" zaxis="0.743 0.669 0" group="5"/>
      <site name="lidar_43" type="box" size="0.1 0.1 0.1" pos="0 0 0.3" rgba="0 1 0 0" zaxis="0.731 0.682 0" group="5"/>
      <site name="lidar_44" type="box" size="0.1 0.1 0.1" pos="0 0 0.3" rgba="0 1 0 0" zaxis="0.719 0.695 0" group="5"/>
      <site name="lidar_45" type="box" size="0.1 0.1 0.1" pos="0 0 0.3" rgba="0 1 0 0" zaxis="0.707 0.707 0" group="5"/>
      <site name="lidar_46" type="box" size="0.1 0.1 0.1" pos="0 0 0.3" rgba="0 1 0 0" zaxis="0.695 0.719 0" group="5"/>
      <site name="lidar_47" type="box" size="0.1 0.1 0.1" pos="0 0 0.3" rgba="0 1 0 0" zaxis="0.682 0.731 0" group="5"/>
      <site name="lidar_48" type="box" size="0.1 0.1 0.1" pos="0 0 0.3" rgba="0 1 0 0" zaxis="0.669 0.743 0" group="5"/>
      <site name="lidar_49" type="box" size="0.1 0.1 0.1" pos="0 0 0.3" rgba="0 1 0 0" zaxis="0.656 0.755 0" group="5"/>
      <site name="lidar_50" type="box" size="0.1 0.1 0.1" pos="0 0 0.3" rgba="0 1 0 0" zaxis="0.643 0.766 0" group="5"/>
      <site name="lidar_51" type="box" size="0.1 0.1 0.1" pos="0 0 0.3" rgba="0 1 0 0" zaxis="0.629 0.777 0" group="5"/>
      <site name="lidar_52" type="box" size="0.1 0.1 0.1" pos="0 0 0.3" rgba="0 1 0 0" zaxis="0.616 0.788 0" group="5"/>
      <site name="lidar_53" type="box" size="0.1 0.1 0.1" pos="0 0 0.3" rgba="0 1 0 0" zaxis="0.602 0.799 0" group="5"/>
      <site name="lidar_54" type="box" size="0.1 0.1 0.1" pos="0 0 0.3" rgba="0 1 0 0" zaxis="0.588 0.809 0" group="5"/>
      <site name="lidar_55" type="box" size="0.1 0.1 0.1" pos="0 0 0.3" rgba="0 1 0 0" zaxis="0.574 0.819 0" group="5"/>
      <site name="lidar_56" type="box" size="0.1 0.1 0.1" pos="0 0 0.3" rgba="0 1 0 0" zaxis="0.559 0.829 0" group="5"/>
      <site name="lidar_57" type="box" size="0.1 0.1 0.1" pos="0 0 0.3" rgba="0 1 0 0" zaxis="0.545 0.839 0" group="5"/>
      <site name="lidar_58" type="box" size="0.1 0.1 0.1" pos="0 0 0.3" rgba="0 1 0 0" zaxis="0.53 0.848 0" group="5"/>
      <site name="lidar_59" type="box" size="0.1 0.1 0.1" pos="0 0 0.3" rgba="0 1 0 0" zaxis="0.515 0.857 0" group="5"/>
      <site name="lidar_60" type="box" size="0.1 0.1 0.1" pos="0 0 0.3" rgba="0 1 0 0" zaxis="0.5 0.866 0" group="5"/>
      <body name="FR_hip" pos="0.1881 -0.04675 0">
        <inertial pos="-0.0049166 0.00762615 -8.865e-05" quat="0.507341 0.514169 0.495027 0.482891" mass="0.68"
          diaginertia="0.000734064 0.000468438 0.000398719"/>
        <joint class="abduction" name="FR_hip_joint"/>
        <geom class="visual" mesh="hip" quat="1 0 0 0"/>
        <geom name="fr_hip" class="hip_right1"/>
        <body name="FR_thigh" pos="0 -0.08 0">
          <inertial pos="-0.00304722 0.019315 -0.0305004" quat="0.65243 -0.0272313 0.0775126 0.753383" mass="1.009"
            diaginertia="0.00478717 0.00460903 0.000709268"/>
          <joint class="hip" name="FR_thigh_joint"/>
          <geom class="visual" mesh="thigh_mirror"/>
          <geom name="fr_thigh1" class="thigh1"/>
          <geom name="fr_thigh2" class="thigh2"/>
          <geom name="fr_thigh3" class="thigh3"/>
          <body name="FR_calf" pos="0 0 -0.213">
            <inertial pos="0.00429862 0.000976676 -0.146197" quat="0.691246 0.00357467 0.00511118 0.722592"
              mass="0.195862" diaginertia="0.00149767 0.00148468 3.58427e-05"/>
            <joint class="knee" name="FR_calf_joint"/>
            <geom class="visual" mesh="calf"/>
            <geom name="fr_calf1" class="calf1"/>
            <geom name="fr_calf2" class="calf2"/>
            <geom name="FR" class="foot"/>
            <site name="FR" pos="0 0 -0.213" type="sphere" size="0.023" group="5"/>
          </body>
        </body>
      </body>
      <body name="FL_hip" pos="0.1881 0.04675 0">
        <inertial pos="-0.0049166 -0.00762615 -8.865e-05" quat="0.482891 0.495027 0.514169 0.507341" mass="0.68"
          diaginertia="0.000734064 0.000468438 0.000398719"/>
        <joint class="abduction" name="FL_hip_joint"/>
        <geom class="visual" mesh="hip"/>
        <geom name="fl_hip" class="hip_left1"/>
        <body name="FL_thigh" pos="0 0.08 0">
          <inertial pos="-0.00304722 -0.019315 -0.0305004" quat="0.753383 0.0775126 -0.0272313 0.65243" mass="1.009"
            diaginertia="0.00478717 0.00460903 0.000709268"/>
          <joint class="hip" name="FL_thigh_joint"/>
          <geom class="visual" mesh="thigh"/>
          <geom name="fl_thigh1" class="thigh1"/>
          <geom name="fl_thigh2" class="thigh2"/>
          <geom name="fl_thigh3" class="thigh3"/>
          <body name="FL_calf" pos="0 0 -0.213">
            <inertial pos="0.00429862 0.000976676 -0.146197" quat="0.691246 0.00357467 0.00511118 0.722592"
              mass="0.195862" diaginertia="0.00149767 0.00148468 3.58427e-05"/>
            <joint class="knee" name="FL_calf_joint"/>
            <geom class="visual" mesh="calf"/>
            <geom name="fl_calf1" class="calf1"/>
            <geom name="fl_calf2" class="calf2"/>
            <geom name="FL" class="foot"/>
            <site name="FL" pos="0 0 -0.213" type="sphere" size="0.023" group="5"/>
          </body>
        </body>
      </body>
      <body name="RR_hip" pos="-0.1881 -0.04675 0">
        <inertial pos="0.0049166 0.00762615 -8.865e-05" quat="0.495027 0.482891 0.507341 0.514169" mass="0.68"
          diaginertia="0.000734064 0.000468438 0.000398719"/>
        <joint class="abduction" name="RR_hip_joint"/>
        <geom class="visual" quat="0 0 0 -1" mesh="hip"/>
        <geom name="rr_hip" class="hip_right1"/>
        <body name="RR_thigh" pos="0 -0.08 0">
          <inertial pos="-0.00304722 0.019315 -0.0305004" quat="0.65243 -0.0272313 0.0775126 0.753383" mass="1.009"
            diaginertia="0.00478717 0.00460903 0.000709268"/>
          <joint class="hip" name="RR_thigh_joint"/>
          <geom class="visual" mesh="thigh_mirror"/>
          <geom name="rr_thigh1" class="thigh1"/>
          <geom name="rr_thigh2" class="thigh2"/>
          <geom name="rr_thigh3" class="thigh3"/>
          <body name="RR_calf" pos="0 0 -0.213">
            <inertial pos="0.00429862 0.000976676 -0.146197" quat="0.691246 0.00357467 0.00511118 0.722592"
              mass="0.195862" diaginertia="0.00149767 0.00148468 3.58427e-05"/>
            <joint class="knee" name="RR_calf_joint"/>
            <geom class="visual" mesh="calf"/>
            <geom name="rr_calf1" class="calf1"/>
            <geom name="rr_calf2" class="calf2"/>
            <geom name="RR" class="foot"/>
            <site name="RR" pos="0 0 -0.213" type="sphere" size="0.023" group="5"/>
          </body>
        </body>
      </body>
      <body name="RL_hip" pos="-0.1881 0.04675 0">
        <inertial pos="0.0049166 -0.00762615 -8.865e-05" quat="0.514169 0.507341 0.482891 0.495027" mass="0.68"
          diaginertia="0.000734064 0.000468438 0.000398719"/>
        <joint class="abduction" name="RL_hip_joint"/>
        <geom class="visual" quat="0 0 1 0" mesh="hip"/>
        <geom name="rl_hip" class="hip_left1"/>
        <body name="RL_thigh" pos="0 0.08 0">
          <inertial pos="-0.00304722 -0.019315 -0.0305004" quat="0.753383 0.0775126 -0.0272313 0.65243" mass="1.009"
            diaginertia="0.00478717 0.00460903 0.000709268"/>
          <joint class="hip" name="RL_thigh_joint"/>
          <geom class="visual" mesh="thigh"/>
          <geom name="rl_thigh1" class="thigh1"/>
          <geom name="rl_thigh2" class="thigh2"/>
          <geom name="rl_thigh3" class="thigh3"/>
          <body name="RL_calf" pos="0 0 -0.213">
            <inertial pos="0.00429862 0.000976676 -0.146197" quat="0.691246 0.00357467 0.00511118 0.722592"
              mass="0.195862" diaginertia="0.00149767 0.00148468 3.58427e-05"/>
            <joint class="knee" name="RL_calf_joint"/>
            <geom class="visual" mesh="calf"/>
            <geom name="rl_calf1" class="calf1"/>
            <geom name="rl_calf2" class="calf2"/>
            <geom name="RL" class="foot"/>
            <site name="RL" pos="0 0 -0.213" type="sphere" size="0.023" group="5"/>
          </body>
        </body>
      </body>
    </body>
  </worldbody>

  <actuator>
    <position class="abduction" name="FR_hip" joint="FR_hip_joint"/>
    <position class="hip" name="FR_thigh" joint="FR_thigh_joint"/>
    <position class="knee" name="FR_calf" joint="FR_calf_joint"/>
    <position class="abduction" name="FL_hip" joint="FL_hip_joint"/>
    <position class="hip" name="FL_thigh" joint="FL_thigh_joint"/>
    <position class="knee" name="FL_calf" joint="FL_calf_joint"/>
    <position class="abduction" name="RR_hip" joint="RR_hip_joint"/>
    <position class="hip" name="RR_thigh" joint="RR_thigh_joint"/>
    <position class="knee" name="RR_calf" joint="RR_calf_joint"/>
    <position class="abduction" name="RL_hip" joint="RL_hip_joint"/>
    <position class="hip" name="RL_thigh" joint="RL_thigh_joint"/>
    <position class="knee" name="RL_calf" joint="RL_calf_joint"/>
  </actuator>

  <sensor>
    <gyro site="imu" name="gyro"/>
    <velocimeter site="imu" name="local_linvel"/>
    <accelerometer site="imu" name="accelerometer"/>
    <framepos objtype="site" objname="imu" name="position"/>
    <framezaxis objtype="site" objname="imu" name="upvector"/>
    <framexaxis objtype="site" objname="imu" name="forwardvector"/>
    <framelinvel objtype="site" objname="imu" name="global_linvel"/>
    <frameangvel objtype="site" objname="imu" name="global_angvel"/>
    <framequat objtype="site" objname="imu" name="orientation"/>
    <framelinvel objtype="site" objname="FR" name="FR_global_linvel"/>
    <framelinvel objtype="site" objname="FL" name="FL_global_linvel"/>
    <framelinvel objtype="site" objname="RR" name="RR_global_linvel"/>
    <framelinvel objtype="site" objname="RL" name="RL_global_linvel"/>
    <framepos objtype="site" objname="FR" name="FR_pos" reftype="site" refname="imu"/>
    <framepos objtype="site" objname="FL" name="FL_pos" reftype="site" refname="imu"/>
    <framepos objtype="site" objname="RR" name="RR_pos" reftype="site" refname="imu"/>
    <framepos objtype="site" objname="RL" name="RL_pos" reftype="site" refname="imu"/>
    <framepos objtype="site" objname="head" name="head_pos"/>


    <rangefinder name="lidar_-60" site="lidar_-60" cutoff="10"/>
    <rangefinder name="lidar_-59" site="lidar_-59" cutoff="10"/>
    <rangefinder name="lidar_-58" site="lidar_-58" cutoff="10"/>
    <rangefinder name="lidar_-57" site="lidar_-57" cutoff="10"/>
    <rangefinder name="lidar_-56" site="lidar_-56" cutoff="10"/>
    <rangefinder name="lidar_-55" site="lidar_-55" cutoff="10"/>
    <rangefinder name="lidar_-54" site="lidar_-54" cutoff="10"/>
    <rangefinder name="lidar_-53" site="lidar_-53" cutoff="10"/>
    <rangefinder name="lidar_-52" site="lidar_-52" cutoff="10"/>
    <rangefinder name="lidar_-51" site="lidar_-51" cutoff="10"/>
    <rangefinder name="lidar_-50" site="lidar_-50" cutoff="10"/>
    <rangefinder name="lidar_-49" site="lidar_-49" cutoff="10"/>
    <rangefinder name="lidar_-48" site="lidar_-48" cutoff="10"/>
    <rangefinder name="lidar_-47" site="lidar_-47" cutoff="10"/>
    <rangefinder name="lidar_-46" site="lidar_-46" cutoff="10"/>
    <rangefinder name="lidar_-45" site="lidar_-45" cutoff="10"/>
    <rangefinder name="lidar_-44" site="lidar_-44" cutoff="10"/>
    <rangefinder name="lidar_-43" site="lidar_-43" cutoff="10"/>
    <rangefinder name="lidar_-42" site="lidar_-42" cutoff="10"/>
    <rangefinder name="lidar_-41" site="lidar_-41" cutoff="10"/>
    <rangefinder name="lidar_-40" site="lidar_-40" cutoff="10"/>
    <rangefinder name="lidar_-39" site="lidar_-39" cutoff="10"/>
    <rangefinder name="lidar_-38" site="lidar_-38" cutoff="10"/>
    <rangefinder name="lidar_-37" site="lidar_-37" cutoff="10"/>
    <rangefinder name="lidar_-36" site="lidar_-36" cutoff="10"/>
    <rangefinder name="lidar_-35" site="lidar_-35" cutoff="10"/>
    <rangefinder name="lidar_-34" site="lidar_-34" cutoff="10"/>
    <rangefinder name="lidar_-33" site="lidar_-33" cutoff="10"/>
    <rangefinder name="lidar_-32" site="lidar_-32" cutoff="10"/>
    <rangefinder name="lidar_-31" site="lidar_-31" cutoff="10"/>
    <rangefinder name="lidar_-30" site="lidar_-30" cutoff="10"/>
    <rangefinder name="lidar_-29" site="lidar_-29" cutoff="10"/>
    <rangefinder name="lidar_-28" site="lidar_-28" cutoff="10"/>
    <rangefinder name="lidar_-27" site="lidar_-27" cutoff="10"/>
    <rangefinder name="lidar_-26" site="lidar_-26" cutoff="10"/>
    <rangefinder name="lidar_-25" site="lidar_-25" cutoff="10"/>
    <rangefinder name="lidar_-24" site="lidar_-24" cutoff="10"/>
    <rangefinder name="lidar_-23" site="lidar_-23" cutoff="10"/>
    <rangefinder name="lidar_-22" site="lidar_-22" cutoff="10"/>
    <rangefinder name="lidar_-21" site="lidar_-21" cutoff="10"/>
    <rangefinder name="lidar_-20" site="lidar_-20" cutoff="10"/>
    <rangefinder name="lidar_-19" site="lidar_-19" cutoff="10"/>
    <rangefinder name="lidar_-18" site="lidar_-18" cutoff="10"/>
    <rangefinder name="lidar_-17" site="lidar_-17" cutoff="10"/>
    <rangefinder name="lidar_-16" site="lidar_-16" cutoff="10"/>
    <rangefinder name="lidar_-15" site="lidar_-15" cutoff="10"/>
    <rangefinder name="lidar_-14" site="lidar_-14" cutoff="10"/>
    <rangefinder name="lidar_-13" site="lidar_-13" cutoff="10"/>
    <rangefinder name="lidar_-12" site="lidar_-12" cutoff="10"/>
    <rangefinder name="lidar_-11" site="lidar_-11" cutoff="10"/>
    <rangefinder name="lidar_-10" site="lidar_-10" cutoff="10"/>
    <rangefinder name="lidar_-9" site="lidar_-9" cutoff="10"/>
    <rangefinder name="lidar_-8" site="lidar_-8" cutoff="10"/>
    <rangefinder name="lidar_-7" site="lidar_-7" cutoff="10"/>
    <rangefinder name="lidar_-6" site="lidar_-6" cutoff="10"/>
    <rangefinder name="lidar_-5" site="lidar_-5" cutoff="10"/>
    <rangefinder name="lidar_-4" site="lidar_-4" cutoff="10"/>
    <rangefinder name="lidar_-3" site="lidar_-3" cutoff="10"/>
    <rangefinder name="lidar_-2" site="lidar_-2" cutoff="10"/>
    <rangefinder name="lidar_-1" site="lidar_-1" cutoff="10"/>
    <rangefinder name="lidar_0" site="lidar_0" cutoff="10"/>
    <rangefinder name="lidar_1" site="lidar_1" cutoff="10"/>
    <rangefinder name="lidar_2" site="lidar_2" cutoff="10"/>
    <rangefinder name="lidar_3" site="lidar_3" cutoff="10"/>
    <rangefinder name="lidar_4" site="lidar_4" cutoff="10"/>
    <rangefinder name="lidar_5" site="lidar_5" cutoff="10"/>
    <rangefinder name="lidar_6" site="lidar_6" cutoff="10"/>
    <rangefinder name="lidar_7" site="lidar_7" cutoff="10"/>
    <rangefinder name="lidar_8" site="lidar_8" cutoff="10"/>
    <rangefinder name="lidar_9" site="lidar_9" cutoff="10"/>
    <rangefinder name="lidar_10" site="lidar_10" cutoff="10"/>
    <rangefinder name="lidar_11" site="lidar_11" cutoff="10"/>
    <rangefinder name="lidar_12" site="lidar_12" cutoff="10"/>
    <rangefinder name="lidar_13" site="lidar_13" cutoff="10"/>
    <rangefinder name="lidar_14" site="lidar_14" cutoff="10"/>
    <rangefinder name="lidar_15" site="lidar_15" cutoff="10"/>
    <rangefinder name="lidar_16" site="lidar_16" cutoff="10"/>
    <rangefinder name="lidar_17" site="lidar_17" cutoff="10"/>
    <rangefinder name="lidar_18" site="lidar_18" cutoff="10"/>
    <rangefinder name="lidar_19" site="lidar_19" cutoff="10"/>
    <rangefinder name="lidar_20" site="lidar_20" cutoff="10"/>
    <rangefinder name="lidar_21" site="lidar_21" cutoff="10"/>
    <rangefinder name="lidar_22" site="lidar_22" cutoff="10"/>
    <rangefinder name="lidar_23" site="lidar_23" cutoff="10"/>
    <rangefinder name="lidar_24" site="lidar_24" cutoff="10"/>
    <rangefinder name="lidar_25" site="lidar_25" cutoff="10"/>
    <rangefinder name="lidar_26" site="lidar_26" cutoff="10"/>
    <rangefinder name="lidar_27" site="lidar_27" cutoff="10"/>
    <rangefinder name="lidar_28" site="lidar_28" cutoff="10"/>
    <rangefinder name="lidar_29" site="lidar_29" cutoff="10"/>
    <rangefinder name="lidar_30" site="lidar_30" cutoff="10"/>
    <rangefinder name="lidar_31" site="lidar_31" cutoff="10"/>
    <rangefinder name="lidar_32" site="lidar_32" cutoff="10"/>
    <rangefinder name="lidar_33" site="lidar_33" cutoff="10"/>
    <rangefinder name="lidar_34" site="lidar_34" cutoff="10"/>
    <rangefinder name="lidar_35" site="lidar_35" cutoff="10"/>
    <rangefinder name="lidar_36" site="lidar_36" cutoff="10"/>
    <rangefinder name="lidar_37" site="lidar_37" cutoff="10"/>
    <rangefinder name="lidar_38" site="lidar_38" cutoff="10"/>
    <rangefinder name="lidar_39" site="lidar_39" cutoff="10"/>
    <rangefinder name="lidar_40" site="lidar_40" cutoff="10"/>
    <rangefinder name="lidar_41" site="lidar_41" cutoff="10"/>
    <rangefinder name="lidar_42" site="lidar_42" cutoff="10"/>
    <rangefinder name="lidar_43" site="lidar_43" cutoff="10"/>
    <rangefinder name="lidar_44" site="lidar_44" cutoff="10"/>
    <rangefinder name="lidar_45" site="lidar_45" cutoff="10"/>
    <rangefinder name="lidar_46" site="lidar_46" cutoff="10"/>
    <rangefinder name="lidar_47" site="lidar_47" cutoff="10"/>
    <rangefinder name="lidar_48" site="lidar_48" cutoff="10"/>
    <rangefinder name="lidar_49" site="lidar_49" cutoff="10"/>
    <rangefinder name="lidar_50" site="lidar_50" cutoff="10"/>
    <rangefinder name="lidar_51" site="lidar_51" cutoff="10"/>
    <rangefinder name="lidar_52" site="lidar_52" cutoff="10"/>
    <rangefinder name="lidar_53" site="lidar_53" cutoff="10"/>
    <rangefinder name="lidar_54" site="lidar_54" cutoff="10"/>
    <rangefinder name="lidar_55" site="lidar_55" cutoff="10"/>
    <rangefinder name="lidar_56" site="lidar_56" cutoff="10"/>
    <rangefinder name="lidar_57" site="lidar_57" cutoff="10"/>
    <rangefinder name="lidar_58" site="lidar_58" cutoff="10"/>
    <rangefinder name="lidar_59" site="lidar_59" cutoff="10"/>
    <rangefinder name="lidar_60" site="lidar_60" cutoff="10"/>
  </sensor>
</mujoco>
